<?xml version="1.0" encoding="utf-8"?>
<!-- This URDF was automatically created by SolidWorks to URDF Exporter! Originally created by Stephen Brawner (brawner@gmail.com) 
     Commit Version: 1.5.1-0-g916b5db  Build Version: 1.5.7152.31018
     For more information, please see http://wiki.ros.org/sw_urdf_exporter -->
<robot
  name="sdr100_description">
  <link
    name="base_link">
    <inertial>
      <origin
        xyz="-0.027147 0.0017466 0.18466"
        rpy="0 0 0" />
      <mass
        value="14.005" />
      <inertia
        ixx="0.2337"
        ixy="-6.8938E-05"
        ixz="-0.0016382"
        iyy="0.27902"
        iyz="-0.001818"
        izz="0.34815" />
    </inertial>
    <visual>
      <origin
        xyz="0 0 0"
        rpy="0 0 0" />
      <geometry>
        <mesh
          filename="package://sdr100_description/meshes/base_link.STL" />
      </geometry>
      <material
        name="">
        <color
          rgba="0.79216 0.81961 0.93333 1" />
      </material>
    </visual>
    <collision>
      <origin
        xyz="0 0 0"
        rpy="0 0 0" />
      <geometry>
        <mesh
          filename="package://sdr100_description/meshes/base_link.STL" />
      </geometry>
    </collision>
  </link>
  <link
    name="wheel_left_link">
    <inertial>
      <origin
        xyz="-6.7556E-10 -0.0009492 -1.3878E-17"
        rpy="0 0 0" />
      <mass
        value="1.2538" />
      <inertia
        ixx="0.0023229"
        ixy="3.5309E-10"
        ixz="-2.0171E-26"
        iyy="0.003868"
        iyz="2.7319E-20"
        izz="0.0023229" />
    </inertial>
    <visual>
      <origin
        xyz="0 0 0"
        rpy="0 0 0" />
      <geometry>
        <mesh
          filename="package://sdr100_description/meshes/wheel_left_link.STL" />
      </geometry>
      <material
        name="">
        <color
          rgba="0.79216 0.81961 0.93333 1" />
      </material>
    </visual>
    <collision>
      <origin
        xyz="0 0 0"
        rpy="0 0 0" />
      <geometry>
        <mesh
          filename="package://sdr100_description/meshes/wheel_left_link.STL" />
      </geometry>
    </collision>
  </link>
  <joint
    name="wheel_left_joint"
    type="continuous">
    <origin
      xyz="0.000285 0.1826 0.085"
      rpy="0 0 0" />
    <parent
      link="base_link" />
    <child
      link="wheel_left_link" />
    <axis
      xyz="0 -1 0" />
  </joint>
  <link
    name="caster_front_left_arm_link">
    <inertial>
      <origin
        xyz="-0.00649482672502799 0.000107163232262494 -0.0157954586591997"
        rpy="0 0 0" />
      <mass
        value="0.0193614075360235" />
      <inertia
        ixx="6.77325076266181E-06"
        ixy="3.83386204811024E-08"
        ixz="-2.48046541785919E-06"
        iyy="7.75858059543586E-06"
        iyz="5.80212768238095E-08"
        izz="6.45129952483067E-06" />
    </inertial>
    <visual>
      <origin
        xyz="0 0 0"
        rpy="0 0 0" />
      <geometry>
        <mesh
          filename="package://sdr100_description/meshes/caster_front_left_arm_link.STL" />
      </geometry>
      <material
        name="">
        <color
          rgba="0.792156862745098 0.819607843137255 0.933333333333333 1" />
      </material>
    </visual>
    <collision>
      <origin
        xyz="0 0 0"
        rpy="0 0 0" />
      <geometry>
        <mesh
          filename="package://sdr100_description/meshes/caster_front_left_arm_link.STL" />
      </geometry>
    </collision>
  </link>
  <joint
    name="caster_front_left_arm_joint"
    type="continuous">
    <origin
      xyz="0.14 0.0875 0.069065"
      rpy="0 0 0" />
    <parent
      link="base_link" />
    <child
      link="caster_front_left_arm_link" />
    <axis
      xyz="0 0 1" />
  </joint>
  <link
    name="caster_front_left_wheel_link">
    <inertial>
      <origin
        xyz="-3.62185296076678E-06 -1.05965067276337E-09 -1.10000967210033E-07"
        rpy="0 0 0" />
      <mass
        value="0.0299454261301273" />
      <inertia
        ixx="5.62799913174224E-06"
        ixy="3.22789619384136E-13"
        ixz="1.20201132501664E-11"
        iyy="9.66736983771267E-06"
        iyz="7.91227262205239E-09"
        izz="5.62772662909753E-06" />
    </inertial>
    <visual>
      <origin
        xyz="0 0 0"
        rpy="0 0 0" />
      <geometry>
        <mesh
          filename="package://sdr100_description/meshes/caster_front_left_wheel_link.STL" />
      </geometry>
      <material
        name="">
        <color
          rgba="0.792156862745098 0.819607843137255 0.933333333333333 1" />
      </material>
    </visual>
    <collision>
      <origin
        xyz="0 0 0"
        rpy="0 0 0" />
      <geometry>
        <mesh
          filename="package://sdr100_description/meshes/caster_front_left_wheel_link.STL" />
      </geometry>
    </collision>
  </link>
  <joint
    name="caster_front_left_wheel_joint"
    type="continuous">
    <origin
      xyz="-0.025 0 -0.044"
      rpy="0 0 0" />
    <parent
      link="caster_front_left_arm_link" />
    <child
      link="caster_front_left_wheel_link" />
    <axis
      xyz="0 -1 0" />
  </joint>
  <link
    name="caster_rear_left_arm_link">
    <inertial>
      <origin
        xyz="-0.00649482672630869 0.000107163230379348 -0.0157954586595195"
        rpy="0 0 0" />
      <mass
        value="0.0193614075395788" />
      <inertia
        ixx="6.77325076308618E-06"
        ixy="3.83386202093924E-08"
        ixz="-2.48046541788534E-06"
        iyy="7.7585805956462E-06"
        iyz="5.80212767813337E-08"
        izz="6.45129952541281E-06" />
    </inertial>
    <visual>
      <origin
        xyz="0 0 0"
        rpy="0 0 0" />
      <geometry>
        <mesh
          filename="package://sdr100_description/meshes/caster_rear_left_arm_link.STL" />
      </geometry>
      <material
        name="">
        <color
          rgba="0.792156862745098 0.819607843137255 0.933333333333333 1" />
      </material>
    </visual>
    <collision>
      <origin
        xyz="0 0 0"
        rpy="0 0 0" />
      <geometry>
        <mesh
          filename="package://sdr100_description/meshes/caster_rear_left_arm_link.STL" />
      </geometry>
    </collision>
  </link>
  <joint
    name="caster_rear_left_arm_joint"
    type="continuous">
    <origin
      xyz="-0.14 0.0875 0.069065"
      rpy="0 0 0" />
    <parent
      link="base_link" />
    <child
      link="caster_rear_left_arm_link" />
    <axis
      xyz="0 0 1" />
  </joint>
  <link
    name="caster_rear_left_wheel_link">
    <inertial>
      <origin
        xyz="-3.62186601504666E-06 -1.11416892378813E-09 -1.09964967201504E-07"
        rpy="0 0 0" />
      <mass
        value="0.0299454261504666" />
      <inertia
        ixx="5.627999127985E-06"
        ixy="3.07713757024694E-13"
        ixz="1.20307407629901E-11"
        iyy="9.66736983458393E-06"
        iyz="7.91226945256632E-09"
        izz="5.62772663371416E-06" />
    </inertial>
    <visual>
      <origin
        xyz="0 0 0"
        rpy="0 0 0" />
      <geometry>
        <mesh
          filename="package://sdr100_description/meshes/caster_rear_left_wheel_link.STL" />
      </geometry>
      <material
        name="">
        <color
          rgba="0.792156862745098 0.819607843137255 0.933333333333333 1" />
      </material>
    </visual>
    <collision>
      <origin
        xyz="0 0 0"
        rpy="0 0 0" />
      <geometry>
        <mesh
          filename="package://sdr100_description/meshes/caster_rear_left_wheel_link.STL" />
      </geometry>
    </collision>
  </link>
  <joint
    name="caster_rear_left_wheel_joint"
    type="continuous">
    <origin
      xyz="-0.025 0 -0.044"
      rpy="0 0 0" />
    <parent
      link="caster_rear_left_arm_link" />
    <child
      link="caster_rear_left_wheel_link" />
    <axis
      xyz="0 -1 0" />
  </joint>
  <link
    name="wheel_right_link">
    <inertial>
      <origin
        xyz="6.75560992726126E-10 0.000949199764109038 1.38777878078145E-17"
        rpy="0 0 0" />
      <mass
        value="1.25378639817448" />
      <inertia
        ixx="0.00232288623035426"
        ixy="3.53093696035845E-10"
        ixz="2.01706527474568E-26"
        iyy="0.00386801315934892"
        iyz="-2.73191471120094E-20"
        izz="0.00232288623035426" />
    </inertial>
    <visual>
      <origin
        xyz="0 0 0"
        rpy="0 0 0" />
      <geometry>
        <mesh
          filename="package://sdr100_description/meshes/wheel_right_link.STL" />
      </geometry>
      <material
        name="">
        <color
          rgba="0.792156862745098 0.819607843137255 0.933333333333333 1" />
      </material>
    </visual>
    <collision>
      <origin
        xyz="0 0 0"
        rpy="0 0 0" />
      <geometry>
        <mesh
          filename="package://sdr100_description/meshes/wheel_right_link.STL" />
      </geometry>
    </collision>
  </link>
  <joint
    name="wheel_right_joint"
    type="continuous">
    <origin
      xyz="0.000285 -0.1826 0.085"
      rpy="0 0 0" />
    <parent
      link="base_link" />
    <child
      link="wheel_right_link" />
    <axis
      xyz="0 1 0" />
  </joint>
  <link
    name="caster_front_right_arm_link">
    <inertial>
      <origin
        xyz="-0.00649482671553142 0.000107163244502592 -0.0157954586565046"
        rpy="0 0 0" />
      <mass
        value="0.0193614075129611" />
      <inertia
        ixx="6.7732507598518E-06"
        ixy="3.83386225031644E-08"
        ixz="-2.48046541754733E-06"
        iyy="7.75858059364342E-06"
        iyz="5.80212772352693E-08"
        izz="6.45129952065998E-06" />
    </inertial>
    <visual>
      <origin
        xyz="0 0 0"
        rpy="0 0 0" />
      <geometry>
        <mesh
          filename="package://sdr100_description/meshes/caster_front_right_arm_link.STL" />
      </geometry>
      <material
        name="">
        <color
          rgba="0.792156862745098 0.819607843137255 0.933333333333333 1" />
      </material>
    </visual>
    <collision>
      <origin
        xyz="0 0 0"
        rpy="0 0 0" />
      <geometry>
        <mesh
          filename="package://sdr100_description/meshes/caster_front_right_arm_link.STL" />
      </geometry>
    </collision>
  </link>
  <joint
    name="caster_front_right_arm_joint"
    type="continuous">
    <origin
      xyz="0.14 -0.0875 0.069065"
      rpy="0 0 0" />
    <parent
      link="base_link" />
    <child
      link="caster_front_right_arm_link" />
    <axis
      xyz="0 0 1" />
  </joint>
  <link
    name="caster_front_right_wheel_link">
    <inertial>
      <origin
        xyz="-3.6218529607529E-06 -1.05965065888558E-09 -1.10000967178808E-07"
        rpy="0 0 0" />
      <mass
        value="0.0299454261301274" />
      <inertia
        ixx="5.62799913174226E-06"
        ixy="3.22789623759125E-13"
        ixz="1.20201132514845E-11"
        iyy="9.66736983771271E-06"
        iyz="7.91227262205017E-09"
        izz="5.62772662909755E-06" />
    </inertial>
    <visual>
      <origin
        xyz="0 0 0"
        rpy="0 0 0" />
      <geometry>
        <mesh
          filename="package://sdr100_description/meshes/caster_front_right_wheel_link.STL" />
      </geometry>
      <material
        name="">
        <color
          rgba="0.792156862745098 0.819607843137255 0.933333333333333 1" />
      </material>
    </visual>
    <collision>
      <origin
        xyz="0 0 0"
        rpy="0 0 0" />
      <geometry>
        <mesh
          filename="package://sdr100_description/meshes/caster_front_right_wheel_link.STL" />
      </geometry>
    </collision>
  </link>
  <joint
    name="caster_front_right_wheel_joint"
    type="continuous">
    <origin
      xyz="-0.025 0 -0.044"
      rpy="0 0 0" />
    <parent
      link="caster_front_right_arm_link" />
    <child
      link="caster_front_right_wheel_link" />
    <axis
      xyz="0 -1 0" />
  </joint>
  <link
    name="caster_rear_right_arm_link">
    <inertial>
      <origin
        xyz="-0.00649482672507373 0.0001071632322064 -0.0157954586592144"
        rpy="0 0 0" />
      <mass
        value="0.0193614075361476" />
      <inertia
        ixx="6.77325076267316E-06"
        ixy="3.83386204727856E-08"
        ixz="-2.48046541786068E-06"
        iyy="7.75858059544428E-06"
        iyz="5.80212768219384E-08"
        izz="6.45129952484793E-06" />
    </inertial>
    <visual>
      <origin
        xyz="0 0 0"
        rpy="0 0 0" />
      <geometry>
        <mesh
          filename="package://sdr100_description/meshes/caster_rear_right_arm_link.STL" />
      </geometry>
      <material
        name="">
        <color
          rgba="0.792156862745098 0.819607843137255 0.933333333333333 1" />
      </material>
    </visual>
    <collision>
      <origin
        xyz="0 0 0"
        rpy="0 0 0" />
      <geometry>
        <mesh
          filename="package://sdr100_description/meshes/caster_rear_right_arm_link.STL" />
      </geometry>
    </collision>
  </link>
  <joint
    name="caster_rear_right_arm_joint"
    type="continuous">
    <origin
      xyz="-0.14 -0.0875 0.069065"
      rpy="0 0 0" />
    <parent
      link="base_link" />
    <child
      link="caster_rear_right_arm_link" />
    <axis
      xyz="0 0 1" />
  </joint>
  <link
    name="caster_rear_right_wheel_link">
    <inertial>
      <origin
        xyz="-3.62186601504666E-06 -1.11416892378813E-09 -1.09964967145992E-07"
        rpy="0 0 0" />
      <mass
        value="0.0299454261504666" />
      <inertia
        ixx="5.62799912798501E-06"
        ixy="3.07713759603956E-13"
        ixz="1.20307407653522E-11"
        iyy="9.66736983458394E-06"
        iyz="7.91226945256643E-09"
        izz="5.62772663371417E-06" />
    </inertial>
    <visual>
      <origin
        xyz="0 0 0"
        rpy="0 0 0" />
      <geometry>
        <mesh
          filename="package://sdr100_description/meshes/caster_rear_right_wheel_link.STL" />
      </geometry>
      <material
        name="">
        <color
          rgba="0.792156862745098 0.819607843137255 0.933333333333333 1" />
      </material>
    </visual>
    <collision>
      <origin
        xyz="0 0 0"
        rpy="0 0 0" />
      <geometry>
        <mesh
          filename="package://sdr100_description/meshes/caster_rear_right_wheel_link.STL" />
      </geometry>
    </collision>
  </link>
  <joint
    name="caster_rear_right_wheel_joint"
    type="continuous">
    <origin
      xyz="-0.025 0 -0.044"
      rpy="0 0 0" />
    <parent
      link="caster_rear_right_arm_link" />
    <child
      link="caster_rear_right_wheel_link" />
    <axis
      xyz="0 -1 0" />
  </joint>
  <link
    name="lidar_link">
    <inertial>
      <origin
        xyz="-0.000148098936093097 -3.20589061074877E-06 -0.0125826292828435"
        rpy="0 0 0" />
      <mass
        value="0.0481184252470374" />
      <inertia
        ixx="3.45484471926661E-05"
        ixy="-2.64745439730844E-09"
        ixz="-7.2542289688968E-08"
        iyy="3.46541300559693E-05"
        iyz="-1.62784619966956E-09"
        izz="5.23974422205502E-05" />
    </inertial>
    <visual>
      <origin
        xyz="0 0 0"
        rpy="0 0 0" />
      <geometry>
        <mesh
          filename="package://sdr100_description/meshes/lidar_link.STL" />
      </geometry>
      <material
        name="">
        <color
          rgba="0.498039215686275 0.498039215686275 0.498039215686275 1" />
      </material>
    </visual>
    <collision>
      <origin
        xyz="0 0 0"
        rpy="0 0 0" />
      <geometry>
        <mesh
          filename="package://sdr100_description/meshes/lidar_link.STL" />
      </geometry>
    </collision>
  </link>
  <joint
    name="lidar_joint"
    type="fixed">
    <origin
      xyz="0 0 0.29442"
      rpy="0 0 0" />
    <parent
      link="base_link" />
    <child
      link="lidar_link" />
    <axis
      xyz="0 0 0" />
  </joint>
  <link
    name="depthcam_link">
    <inertial>
      <origin
        xyz="0.00150773539014118 0.00140604320859637 0.0124766080720145"
        rpy="0 0 0" />
      <mass
        value="0.0364722960761443" />
      <inertia
        ixx="2.34030027480876E-05"
        ixy="2.10299133958588E-07"
        ixz="1.01558544663176E-08"
        iyy="3.5060662845294E-06"
        iyz="1.71385186514591E-09"
        izz="2.36116372449809E-05" />
    </inertial>
    <visual>
      <origin
        xyz="0 0 0"
        rpy="0 0 0" />
      <geometry>
        <mesh
          filename="package://sdr100_description/meshes/depthcam_link.STL" />
      </geometry>
      <material
        name="">
        <color
          rgba="0.701960784313725 0.701960784313725 0.701960784313725 1" />
      </material>
    </visual>
    <collision>
      <origin
        xyz="0 0 0"
        rpy="0 0 0" />
      <geometry>
        <mesh
          filename="package://sdr100_description/meshes/depthcam_link.STL" />
      </geometry>
    </collision>
  </link>
  <joint
    name="depthcam_joint"
    type="fixed">
    <origin
      xyz="0.20804 0 0.057456"
      rpy="0 -0.43633 0" />
    <parent
      link="base_link" />
    <child
      link="depthcam_link" />
    <axis
      xyz="0 0 0" />
  </joint>
  <link
    name="rgb_camera_link">
    <inertial>
      <origin
        xyz="-4.96614485655883E-10 -3.57408547202454E-13 -0.0100253875802096"
        rpy="0 0 0" />
      <mass
        value="0.0605927782252049" />
      <inertia
        ixx="6.99191996508856E-06"
        ixy="-1.38979846014596E-11"
        ixz="4.60006097227063E-13"
        iyy="2.54302596557141E-05"
        iyz="5.09059527310496E-17"
        izz="2.70334159831627E-05" />
    </inertial>
    <visual>
      <origin
        xyz="0 0 0"
        rpy="0 0 0" />
      <geometry>
        <mesh
          filename="package://sdr100_description/meshes/rgb_camera_link.STL" />
      </geometry>
      <material
        name="">
        <color
          rgba="0.250980392156863 0.250980392156863 0.250980392156863 1" />
      </material>
    </visual>
    <collision>
      <origin
        xyz="0 0 0"
        rpy="0 0 0" />
      <geometry>
        <mesh
          filename="package://sdr100_description/meshes/rgb_camera_link.STL" />
      </geometry>
    </collision>
  </link>
  <joint
    name="rgb_camera_joint"
    type="fixed">
    <origin
      xyz="-0.21467 0 0.063165"
      rpy="-1.5708 0 1.5708" />
    <parent
      link="base_link" />
    <child
      link="rgb_camera_link" />
    <axis
      xyz="0 0 0" />
  </joint>
  <link
    name="imu_link">
    <inertial>
      <origin
        xyz="-6.93505865298899E-05 2.10656642645062E-05 -0.00172272577964397"
        rpy="0 0 0" />
      <mass
        value="0.000911356888660494" />
      <inertia
        ixx="2.85410348210609E-08"
        ixy="-2.22197427857067E-10"
        ixz="7.87903579180148E-11"
        iyy="4.99346433608486E-08"
        iyz="-4.13194761846756E-11"
        izz="7.78569805080493E-08" />
    </inertial>
    <visual>
      <origin
        xyz="0 0 0"
        rpy="0 0 0" />
      <geometry>
        <mesh
          filename="package://sdr100_description/meshes/imu_link.STL" />
      </geometry>
      <material
        name="">
        <color
          rgba="0.792156862745098 0.819607843137255 0.933333333333333 1" />
      </material>
    </visual>
    <collision>
      <origin
        xyz="0 0 0"
        rpy="0 0 0" />
      <geometry>
        <mesh
          filename="package://sdr100_description/meshes/imu_link.STL" />
      </geometry>
    </collision>
  </link>
  <joint
    name="imu_joint"
    type="fixed">
    <origin
      xyz="0.0915 -0.0003 0.16272"
      rpy="0 0 0" />
    <parent
      link="base_link" />
    <child
      link="imu_link" />
    <axis
      xyz="0 0 0" />
  </joint>
</robot>